<?xml version="1.0"?>
<robot xmlns:xacro="http://www.ros.org/wiki/xacro" name="arm">

  <link name="arm_base">
    <inertial>
      <origin xyz="7.7128E-09 -0.063005 -3.01969999961422E-08" rpy="0 0 0" />
      <mass value="1.6004" />
      <inertia ixx="0.00552196561445819" ixy="7.9550614501301E-10" ixz="-1.34378458924839E-09" iyy="0.00352397447953875" iyz="-1.10071809773382E-08" izz="0.00553739792746489" />
    </inertial>
    <visual>
      <origin xyz="0 0 0" rpy="0 0 0" />
      <geometry>
        <mesh filename="package://robot_description/meshes/arm_base.stl" />
      </geometry>
      <material name="">
        <color rgba="0.79216 0.81961 0.93333 1" />
      </material>
    </visual>
    <collision>
      <origin xyz="0 0 0" rpy="0 0 0" />
      <geometry>
        <mesh filename="package://robot_description/meshes/arm_base.stl" />
      </geometry>
    </collision>
  </link>

  <link name="bicep">
    <inertial>
      <origin xyz="0.12821 3.5589E-06 0.052492" rpy="0 0 0" />
      <mass value="1.1198" />
      <inertia ixx="0.0012474" ixy="-5.4004E-07" ixz="-0.0013148" iyy="0.0072923" iyz="-1.8586E-07" izz="0.0068178" />
    </inertial>
    <visual>
      <origin xyz="0 0 0" rpy="0 -1.5708 0" />
      <geometry>
        <mesh filename="package://robot_description/meshes/bicep.stl" />
      </geometry>
      <material name="">
        <color rgba="0.79216 0.81961 0.93333 1" />
      </material>
    </visual>
    <collision>
      <origin xyz="0 0 0" rpy="0 -1.5708 0" />
      <geometry>
        <mesh filename="package://robot_description/meshes/bicep.stl" />
      </geometry>
    </collision>
  </link>


  <link name="bottom_wrist">
    <inertial>
      <origin xyz="-9.1053E-08 -0.069257 -1.86629999995759E-07" rpy="0 0 0" />
      <mass value="0.27721" />
      <inertia ixx="0.00104290750143942" ixy="4.37155302268076E-09" ixz="-2.45049603914627E-09" iyy="0.000380518373895034" iyz="-7.56009835172156E-09" izz="0.00106006525067445" />
    </inertial>
    <visual>
      <origin xyz="0 0 0.13522" rpy="3.14 0 1.5708" />
      <geometry>
        <mesh filename="package://robot_description/meshes/wrist.stl" />
      </geometry>
      <material name="">
        <color rgba="0.79216 0.81961 0.93333 1" />
      </material>
    </visual>
    <collision>
      <origin xyz="0 0 0.13522" rpy="3.14 0 1.5708" />
      <geometry>
        <mesh filename="package://robot_description/meshes/wrist.stl" />
      </geometry>
    </collision>
  </link>

  <link name="elbow">
    <inertial>
      <origin xyz="-0.11109 1.1476E-08 0.046469" rpy="0 0 0" />
      <mass value="0.84845" />
      <inertia ixx="0.00079656" ixy="-7.8011E-10" ixz="0.00053616" iyy="0.003576" iyz="4.6326E-10" izz="0.0033698" />
    </inertial>
    <visual>
      <origin xyz="0.0 0.05163 0.20994" rpy="0 -1.5708 0" />
      <geometry>
        <mesh filename="package://robot_description/meshes/elbow.stl" />
      </geometry>
      <material name="">
        <color rgba="0.79216 0.81961 0.93333 1" />
      </material>
    </visual>
    <collision>
      <origin xyz="0.0 0.05163 0.20994" rpy="0 -1.5708 0" />
      <geometry>
        <mesh filename="package://robot_description/meshes/elbow.stl" />
      </geometry>
    </collision>
  </link>

  <link name="top_wrist">
    <inertial>
      <origin xyz="-9.1053E-08 -0.069257 -1.86629999995759E-07" rpy="0 0 0" />
      <mass value="0.27721" />
      <inertia ixx="0.00104290750143942" ixy="4.37155302268076E-09" ixz="-2.45049603914627E-09" iyy="0.000380518373895034" iyz="-7.56009835172156E-09" izz="0.00106006525067445" />
    </inertial>
    <visual>
      <origin xyz="0 0 0.13522" rpy="3.14 0 1.5708" />
      <geometry>
        <mesh filename="package://robot_description/meshes/wrist.stl" />
      </geometry>
      <material name="">
        <color rgba="0.79216 0.81961 0.93333 1" />
      </material>
    </visual>
    <collision>
      <origin xyz="0 0 0.13522" rpy="3.14 0 1.5708" />
      <geometry>
        <mesh filename="package://robot_description/meshes/wrist.stl" />
      </geometry>
    </collision>
  </link>

  <joint name="arm_base_joint" type="continuous">
    <axis xyz="0 0 1"/>
    <parent link="base_link"/>
    <child link="arm_base"/>
    <origin rpy="0 0 0" xyz="0.0 0.0 0.145"/>
  </joint>

  <joint name="shoulder_joint" type="continuous">
    <axis xyz="0 1 0"/>
    <parent link="arm_base"/>
    <child link="bicep"/>
    <origin rpy="0 0 1.5708" xyz="-0.05166 0.0 0.20271"/>
  </joint>

  <joint name="bottom_wrist_joint" type="continuous">
    <axis xyz="0 1 0"/>
    <parent link="bicep"/>
    <child link="bottom_wrist"/>
    <origin rpy="0 0 0" xyz="0.0 -0.05194 0.269"/>
  </joint>

  <joint name="elbow_joint" type="continuous">
    <axis xyz="0 0 1"/>
    <parent link="bottom_wrist"/>
    <child link="elbow"/>
    <origin rpy="0 0 0" xyz="0.0 0 0.13522"/>
  </joint>

  <joint name="top_wrist_joint" type="continuous">
    <axis xyz="0 1 0"/>
    <parent link="elbow"/>
    <child link="top_wrist"/>
    <origin rpy="0 0 0" xyz="0.0 0 0.20994"/>
  </joint>

  <!-- Gripper -->


  <joint name="wrist_gripper_joint" type="continuous">
    <axis xyz="0 0 1"/>
    <parent link="top_wrist"/>
    <child link="test__link"/>
    <origin rpy="0 0 0" xyz="0.0 0 0.11"/>
  </joint>

   <joint name="test_link_0_joint_4" type="fixed">
    <parent link="test__link_0"/>
    <child link="test__link_0_clone_0"/>
    <origin xyz="-0.085    0       0.01749" rpy="-0.39713  1.57078 -0.39713"/>
  </joint>
  <joint name="test_link_joint_2" type="fixed">
    <parent link="test__link"/>
    <child link="test__link_0_clone"/>
    <origin xyz="0.0625 0     0.175" rpy="-3.14159  1.57079 -3.14159"/>
  </joint>
  <joint name="test_link_joint_3" type="prismatic">
    <parent link="test__link"/>
    <child link="test__link_0"/>
    <origin xyz="-0.0625  0      0.15" rpy="3.14159 1.57079 3.14159"/>
    <axis xyz="0 0 1"/>
    <limit lower="-0.01" upper="0.075" effort="1e6" velocity="1e6"/>
  </joint>
  <link name="test__link">
    <inertial>
      <mass value="0.46875"/>
      <origin xyz="0 0 0" rpy="0 0 0"/>
      <inertia ixx="0.00019531" ixy="0" ixz="0" iyy="0.00097656" iyz="0" izz="0.00097656"/>
    </inertial>
    <collision name="test__collision">
      <origin xyz="0   0   0.05" rpy="0 0 0"/>
      <geometry>
        <box size="0.15 0.05 0.05"/>
      </geometry>
    </collision>
    <visual name="test__visual">
      <origin xyz="0   0   0.05" rpy="0 0 0"/>
      <geometry>
        <box size="0.15 0.05 0.05"/>
      </geometry>
    </visual>
  </link>
  <link name="test__link_0">
    <inertial>
      <mass value="0.234375"/>
      <origin xyz="0 0 0" rpy="0 0 0"/>
      <inertia ixx="6.104e-05" ixy="0" ixz="0" iyy="0.00045166" iyz="0" izz="0.00048828"/>
    </inertial>
    <collision name="test__collision">
      <origin xyz="0 0 0" rpy="0 0 0"/>
      <geometry>
        <box size="0.15 0.05 0.025"/>
      </geometry>
    </collision>
    <visual name="test__visual">
      <origin xyz="0 0 0" rpy="0 0 0"/>
      <geometry>
        <box size="0.15 0.05 0.025"/>
      </geometry>
    </visual>
  </link>
  <link name="test__link_0_clone">
    <inertial>
      <mass value="0.3125"/>
      <origin xyz="0 0 0" rpy="0 0 0"/>
      <inertia ixx="8.138e-05" ixy="0" ixz="0" iyy="0.00105794" iyz="0" izz="0.00110677"/>
    </inertial>
    <collision name="test__collision">
      <origin xyz="0 0 0" rpy="0 0 0"/>
      <geometry>
        <box size="0.2 0.05 0.025"/>
      </geometry>
    </collision>
    <visual name="test__visual">
      <origin xyz="0 0 0" rpy="0 0 0"/>
      <geometry>
        <box size="0.2 0.05 0.025"/>
      </geometry>
    </visual>
  </link>
  <link name="test__link_0_clone_0">
    <inertial>
      <mass value="0.075"/>
      <origin xyz="0 0 0" rpy="0 0 0"/>
      <inertia ixx="1.813e-05" ixy="0" ixz="0" iyy="2.5e-05" iyz="0" izz="3.812e-05"/>
    </inertial>
    <collision name="test__collision">
      <origin xyz="0 0 0" rpy="0 0 0"/>
      <geometry>
        <box size="0.06 0.05 0.02"/>
      </geometry>
    </collision>
    <visual name="test__visual">
      <origin xyz="0 0 0" rpy="0 0 0"/>
      <geometry>
        <box size="0.06 0.05 0.02"/>
      </geometry>
    </visual>
  </link>

</robot>