<?xml version="1.0"?>
<robot xmlns:xacro="http://www.ros.org/wiki/xacro" name="base">
  
  <link name="base_footprint">
    <inertial>
      <origin xyz="0.0030946 4.78250032638821E-11 0.053305" rpy="0 0 0" />
      <mass value="0" />
      <inertia ixx="0.0833333" ixy="-1.03781944357671E-10" ixz="0.00763014265820928" iyy="0.192708" iyz="1.09578155845563E-12" izz="0.242708" />
    </inertial>
  </link>
  
  <joint name="base_to_footprint_joint" type="fixed">
    <axis xyz="0 0 1"/>
    <parent link ="base_footprint"/>
    <child link ="base_link"/>
    <origin rpy ="0 0 0" xyz= "0 0 0.053305"/>
  </joint>

  <link name="base_link">
    <inertial>
      <origin xyz="0.0030946 4.78250032638821E-11 0.053305" rpy="0 0 0" />
      <!-- <mass value="47.873" />
      <inertia ixx="0.774276574699151" ixy="-1.03781944357671E-10" ixz="0.00763014265820928" iyy="1.64933255189991" iyz="1.09578155845563E-12" izz="2.1239326987473" />
    </inertial> -->
      <mass value="5" />
      <inertia ixx="0.0833333" ixy="-1.03781944357671E-10" ixz="0.00763014265820928" iyy="0.192708" iyz="1.09578155845563E-12" izz="0.242708" />
    </inertial>
    <visual>
      <origin xyz="0 0 0" rpy="1.5707963267949 0 3.14" />
      <geometry>
        <mesh filename="package://robot_description/meshes/robot_base.stl" />
      </geometry>
      <material name="">
        <color rgba="0.79216 0.81961 0.93333 1" />
      </material>
    </visual>
    <collision>
      <origin xyz="0 0 0" rpy="1.5707963267949 0 3.14" />
      <geometry>
        <mesh filename="package://robot_description/meshes/robot_base.stl" />
      </geometry>
    </collision>
  </link>

  <link name="front_left_wheel">
    <inertial>
      <origin xyz="-4.1867E-18 0.0068085 -1.65658661799998E-18" rpy="0 0 0" />
      <mass value="2.6578" />
      <inertia ixx="0.00856502765719703" ixy="1.5074118157338E-19" ixz="-4.78150098725052E-19" iyy="0.013670640432096" iyz="-2.68136447099727E-19" izz="0.00856502765719703" />
    </inertial>
    <visual>
      <origin xyz="0 0 0" rpy="-1.5707963267949 0 0" />
      <geometry>
        <mesh filename="package://robot_description/meshes/wheel.stl" />
      </geometry>
      <material name="">
        <color rgba="0.79216 0.81961 0.93333 1" />
      </material>
    </visual>
    <collision>
      <origin xyz="0 0 0" rpy="-1.5707963267949 0 0" />
      <geometry>
        <mesh filename="package://robot_description/meshes/wheel.stl" />
      </geometry>
    </collision>
  </link>

  <link name="front_right_wheel">
    <inertial>
      <origin xyz="-4.1867E-18 0.0068085 -1.65658661799998E-18" rpy="0 0 0" />
      <mass value="2.6578" />
      <inertia ixx="0.00856502765719703" ixy="1.5074118157338E-19" ixz="-4.78150098725052E-19" iyy="0.013670640432096" iyz="-2.68136447099727E-19" izz="0.00856502765719703" />
    </inertial>
    <visual>
      <origin xyz="0 0 0" rpy="1.5707963267949 0 0" />
      <geometry>
        <mesh filename="package://robot_description/meshes/wheel.stl" />
      </geometry>
      <material name="">
        <color rgba="0.79216 0.81961 0.93333 1" />
      </material>
    </visual>
    <collision>
      <origin xyz="0 0 0" rpy="1.5707963267949 0 0" />
      <geometry>
        <mesh filename="package://robot_description/meshes/wheel.stl" />
      </geometry>
    </collision>
  </link>

  <link name="rear_left_wheel">
    <inertial>
      <origin xyz="-4.1867E-18 0.0068085 -1.65658661799998E-18" rpy="0 0 0" />
      <mass value="2.6578" />
      <inertia ixx="0.00856502765719703" ixy="1.5074118157338E-19" ixz="-4.78150098725052E-19" iyy="0.013670640432096" iyz="-2.68136447099727E-19" izz="0.00856502765719703" />
    </inertial>
    <visual>
      <origin xyz="0 0 0" rpy="-1.5707963267949 0 0" />
      <geometry>
        <mesh filename="package://robot_description/meshes/wheel.stl" />
      </geometry>
      <material name="">
        <color rgba="0.79216 0.81961 0.93333 1" />
      </material>
    </visual>
    <collision>
      <origin xyz="0 0 0" rpy="-1.5707963267949 0 0" />
      <geometry>
        <mesh filename="package://robot_description/meshes/wheel.stl" />
      </geometry>
    </collision>
  </link>

  <link name="rear_right_wheel">
    <inertial>
      <origin xyz="-4.1867E-18 0.0068085 -1.65658661799998E-18" rpy="0 0 0" />
      <mass value="2.6578" />
      <inertia ixx="0.00856502765719703" ixy="1.5074118157338E-19" ixz="-4.78150098725052E-19" iyy="0.013670640432096" iyz="-2.68136447099727E-19" izz="0.00856502765719703" />
    </inertial>
    <visual>
      <origin xyz="0 0 0" rpy="1.5707963267949 0 0" />
      <geometry>
        <mesh filename="package://robot_description/meshes/wheel.stl" />
      </geometry>
      <material name="">
        <color rgba="0.79216 0.81961 0.93333 1" />
      </material>
    </visual>
    <collision>
      <origin xyz="0 0 0" rpy="1.5707963267949 0 0" />
      <geometry>
        <mesh filename="package://robot_description/meshes/wheel.stl" />
      </geometry>
    </collision>
  </link>


  <joint name="front_left_wheel_joint" type="continuous">
    <axis xyz="0 1 0"/>
    <parent link ="base_link"/>
    <child link ="front_left_wheel"/>
    <origin rpy ="0 0 0" xyz= "0.220 0.250 0"/>
  </joint>


  <joint name="front_right_wheel_joint" type="continuous">
    <axis xyz="0 1 0"/>
    <parent link ="base_link"/>
    <child link ="front_right_wheel"/>
    <origin rpy ="0 0 0" xyz= "0.220 -0.250 0"/>
  </joint>

  <joint name="rear_left_wheel_joint" type="continuous">
    <axis xyz="0 1 0"/>
    <parent link ="base_link"/>
    <child link ="rear_left_wheel"/>
    <origin rpy ="0 0 0" xyz= "-0.220 0.250 0"/>
  </joint>

  <joint name="rear_right_wheel_joint" type="continuous">
    <axis xyz="0 1 0"/>
    <parent link ="base_link"/>
    <child link ="rear_right_wheel"/>
    <origin rpy ="0 0 0" xyz= "-0.220 -0.250 0"/>
  </joint>
</robot>