<?xml version="1.0" ?>
<!-- =================================================================================== -->
<!-- |    This document was autogenerated by xacro from mobile_kinect_manipulator.urdf.xacro | -->
<!-- |    EDITING THIS FILE BY HAND IS NOT RECOMMENDED                                 | -->
<!-- =================================================================================== -->
<robot name="mobile_manipulator">
  <link name="base_footprint">
    <inertial>
      <origin rpy="0 0 0" xyz="0.0030946 4.78250032638821E-11 0.053305"/>
      <mass value="0"/>
      <inertia ixx="0.0833333" ixy="-1.03781944357671E-10" ixz="0.00763014265820928" iyy="0.192708" iyz="1.09578155845563E-12" izz="0.242708"/>
    </inertial>
  </link>
  <joint name="base_to_footprint_joint" type="fixed">
    <axis xyz="0 0 1"/>
    <parent link="base_footprint"/>
    <child link="base_link"/>
    <origin rpy="0 0 0" xyz="0 0 0.053305"/>
  </joint>
  <link name="base_link">
    <inertial>
      <origin rpy="0 0 0" xyz="0.0030946 4.78250032638821E-11 0.053305"/>
      <!-- <mass value="47.873" />
      <inertia ixx="0.774276574699151" ixy="-1.03781944357671E-10" ixz="0.00763014265820928" iyy="1.64933255189991" iyz="1.09578155845563E-12" izz="2.1239326987473" />
    </inertial> -->
      <mass value="5"/>
      <inertia ixx="0.0833333" ixy="-1.03781944357671E-10" ixz="0.00763014265820928" iyy="0.192708" iyz="1.09578155845563E-12" izz="0.242708"/>
    </inertial>
    <visual>
      <origin rpy="1.5707963267949 0 3.14" xyz="0 0 0"/>
      <geometry>
        <mesh filename="package://robot_description/meshes/robot_base.stl"/>
      </geometry>
      <material name="">
        <color rgba="0.79216 0.81961 0.93333 1"/>
      </material>
    </visual>
    <collision>
      <origin rpy="1.5707963267949 0 3.14" xyz="0 0 0"/>
      <geometry>
        <mesh filename="package://robot_description/meshes/robot_base.stl"/>
      </geometry>
    </collision>
  </link>
  <link name="front_left_wheel">
    <inertial>
      <origin rpy="0 0 0" xyz="-4.1867E-18 0.0068085 -1.65658661799998E-18"/>
      <mass value="2.6578"/>
      <inertia ixx="0.00856502765719703" ixy="1.5074118157338E-19" ixz="-4.78150098725052E-19" iyy="0.013670640432096" iyz="-2.68136447099727E-19" izz="0.00856502765719703"/>
    </inertial>
    <visual>
      <origin rpy="-1.5707963267949 0 0" xyz="0 0 0"/>
      <geometry>
        <mesh filename="package://robot_description/meshes/wheel.stl"/>
      </geometry>
      <material name="">
        <color rgba="0.79216 0.81961 0.93333 1"/>
      </material>
    </visual>
    <collision>
      <origin rpy="-1.5707963267949 0 0" xyz="0 0 0"/>
      <geometry>
        <mesh filename="package://robot_description/meshes/wheel.stl"/>
      </geometry>
    </collision>
  </link>
  <link name="front_right_wheel">
    <inertial>
      <origin rpy="0 0 0" xyz="-4.1867E-18 0.0068085 -1.65658661799998E-18"/>
      <mass value="2.6578"/>
      <inertia ixx="0.00856502765719703" ixy="1.5074118157338E-19" ixz="-4.78150098725052E-19" iyy="0.013670640432096" iyz="-2.68136447099727E-19" izz="0.00856502765719703"/>
    </inertial>
    <visual>
      <origin rpy="1.5707963267949 0 0" xyz="0 0 0"/>
      <geometry>
        <mesh filename="package://robot_description/meshes/wheel.stl"/>
      </geometry>
      <material name="">
        <color rgba="0.79216 0.81961 0.93333 1"/>
      </material>
    </visual>
    <collision>
      <origin rpy="1.5707963267949 0 0" xyz="0 0 0"/>
      <geometry>
        <mesh filename="package://robot_description/meshes/wheel.stl"/>
      </geometry>
    </collision>
  </link>
  <link name="rear_left_wheel">
    <inertial>
      <origin rpy="0 0 0" xyz="-4.1867E-18 0.0068085 -1.65658661799998E-18"/>
      <mass value="2.6578"/>
      <inertia ixx="0.00856502765719703" ixy="1.5074118157338E-19" ixz="-4.78150098725052E-19" iyy="0.013670640432096" iyz="-2.68136447099727E-19" izz="0.00856502765719703"/>
    </inertial>
    <visual>
      <origin rpy="-1.5707963267949 0 0" xyz="0 0 0"/>
      <geometry>
        <mesh filename="package://robot_description/meshes/wheel.stl"/>
      </geometry>
      <material name="">
        <color rgba="0.79216 0.81961 0.93333 1"/>
      </material>
    </visual>
    <collision>
      <origin rpy="-1.5707963267949 0 0" xyz="0 0 0"/>
      <geometry>
        <mesh filename="package://robot_description/meshes/wheel.stl"/>
      </geometry>
    </collision>
  </link>
  <link name="rear_right_wheel">
    <inertial>
      <origin rpy="0 0 0" xyz="-4.1867E-18 0.0068085 -1.65658661799998E-18"/>
      <mass value="2.6578"/>
      <inertia ixx="0.00856502765719703" ixy="1.5074118157338E-19" ixz="-4.78150098725052E-19" iyy="0.013670640432096" iyz="-2.68136447099727E-19" izz="0.00856502765719703"/>
    </inertial>
    <visual>
      <origin rpy="1.5707963267949 0 0" xyz="0 0 0"/>
      <geometry>
        <mesh filename="package://robot_description/meshes/wheel.stl"/>
      </geometry>
      <material name="">
        <color rgba="0.79216 0.81961 0.93333 1"/>
      </material>
    </visual>
    <collision>
      <origin rpy="1.5707963267949 0 0" xyz="0 0 0"/>
      <geometry>
        <mesh filename="package://robot_description/meshes/wheel.stl"/>
      </geometry>
    </collision>
  </link>
  <joint name="front_left_wheel_joint" type="continuous">
    <axis xyz="0 1 0"/>
    <parent link="base_link"/>
    <child link="front_left_wheel"/>
    <origin rpy="0 0 0" xyz="0.220 0.250 0"/>
  </joint>
  <joint name="front_right_wheel_joint" type="continuous">
    <axis xyz="0 1 0"/>
    <parent link="base_link"/>
    <child link="front_right_wheel"/>
    <origin rpy="0 0 0" xyz="0.220 -0.250 0"/>
  </joint>
  <joint name="rear_left_wheel_joint" type="continuous">
    <axis xyz="0 1 0"/>
    <parent link="base_link"/>
    <child link="rear_left_wheel"/>
    <origin rpy="0 0 0" xyz="-0.220 0.250 0"/>
  </joint>
  <joint name="rear_right_wheel_joint" type="continuous">
    <axis xyz="0 1 0"/>
    <parent link="base_link"/>
    <child link="rear_right_wheel"/>
    <origin rpy="0 0 0" xyz="-0.220 -0.250 0"/>
  </joint>
  <!--############################## ARM ########################################-->
  <link name="arm_base">
    <inertial>
      <origin rpy="0 0 0" xyz="7.7128E-09 -0.063005 -3.01969999961422E-08"/>
      <mass value="1.6004"/>
      <inertia ixx="0.00552196561445819" ixy="7.9550614501301E-10" ixz="-1.34378458924839E-09" iyy="0.00352397447953875" iyz="-1.10071809773382E-08" izz="0.00553739792746489"/>
    </inertial>
    <visual>
      <origin rpy="0 0 0" xyz="0 0 0"/>
      <geometry>
        <mesh filename="package://robot_description/meshes/arm_base.stl"/>
      </geometry>
      <material name="">
        <color rgba="0.79216 0.81961 0.93333 1"/>
      </material>
    </visual>
    <collision>
      <origin rpy="0 0 0" xyz="0 0 0"/>
      <geometry>
        <mesh filename="package://robot_description/meshes/arm_base.stl"/>
      </geometry>
    </collision>
  </link>
  <link name="bicep">
    <inertial>
      <origin rpy="0 0 0" xyz="0.12821 3.5589E-06 0.052492"/>
      <mass value="1.1198"/>
      <inertia ixx="0.0012474" ixy="-5.4004E-07" ixz="-0.0013148" iyy="0.0072923" iyz="-1.8586E-07" izz="0.0068178"/>
    </inertial>
    <visual>
      <origin rpy="0 -1.5708 0" xyz="0 0 0"/>
      <geometry>
        <mesh filename="package://robot_description/meshes/bicep.stl"/>
      </geometry>
      <material name="">
        <color rgba="0.79216 0.81961 0.93333 1"/>
      </material>
    </visual>
    <collision>
      <origin rpy="0 -1.5708 0" xyz="0 0 0"/>
      <geometry>
        <mesh filename="package://robot_description/meshes/bicep.stl"/>
      </geometry>
    </collision>
  </link>
  <link name="bottom_wrist">
    <inertial>
      <origin rpy="0 0 0" xyz="-9.1053E-08 -0.069257 -1.86629999995759E-07"/>
      <mass value="0.27721"/>
      <inertia ixx="0.00104290750143942" ixy="4.37155302268076E-09" ixz="-2.45049603914627E-09" iyy="0.000380518373895034" iyz="-7.56009835172156E-09" izz="0.00106006525067445"/>
    </inertial>
    <visual>
      <origin rpy="3.14 0 1.5708" xyz="0 0 0.13522"/>
      <geometry>
        <mesh filename="package://robot_description/meshes/wrist.stl"/>
      </geometry>
      <material name="">
        <color rgba="0.79216 0.81961 0.93333 1"/>
      </material>
    </visual>
    <collision>
      <origin rpy="3.14 0 1.5708" xyz="0 0 0.13522"/>
      <geometry>
        <mesh filename="package://robot_description/meshes/wrist.stl"/>
      </geometry>
    </collision>
  </link>
  <link name="elbow">
    <inertial>
      <origin rpy="0 0 0" xyz="-0.11109 1.1476E-08 0.046469"/>
      <mass value="0.84845"/>
      <inertia ixx="0.00079656" ixy="-7.8011E-10" ixz="0.00053616" iyy="0.003576" iyz="4.6326E-10" izz="0.0033698"/>
    </inertial>
    <visual>
      <origin rpy="0 -1.5708 0" xyz="0.0 0.05163 0.20994"/>
      <geometry>
        <mesh filename="package://robot_description/meshes/elbow.stl"/>
      </geometry>
      <material name="">
        <color rgba="0.79216 0.81961 0.93333 1"/>
      </material>
    </visual>
    <collision>
      <origin rpy="0 -1.5708 0" xyz="0.0 0.05163 0.20994"/>
      <geometry>
        <mesh filename="package://robot_description/meshes/elbow.stl"/>
      </geometry>
    </collision>
  </link>
  <link name="top_wrist">
    <inertial>
      <origin rpy="0 0 0" xyz="-9.1053E-08 -0.069257 -1.86629999995759E-07"/>
      <mass value="0.27721"/>
      <inertia ixx="0.00104290750143942" ixy="4.37155302268076E-09" ixz="-2.45049603914627E-09" iyy="0.000380518373895034" iyz="-7.56009835172156E-09" izz="0.00106006525067445"/>
    </inertial>
    <visual>
      <origin rpy="3.14 0 1.5708" xyz="0 0 0.13522"/>
      <geometry>
        <mesh filename="package://robot_description/meshes/wrist.stl"/>
      </geometry>
      <material name="">
        <color rgba="0.79216 0.81961 0.93333 1"/>
      </material>
    </visual>
    <collision>
      <origin rpy="3.14 0 1.5708" xyz="0 0 0.13522"/>
      <geometry>
        <mesh filename="package://robot_description/meshes/wrist.stl"/>
      </geometry>
    </collision>
  </link>
  <joint name="arm_base_joint" type="continuous">
    <axis xyz="0 0 1"/>
    <parent link="base_link"/>
    <child link="arm_base"/>
    <origin rpy="0 0 0" xyz="0.0 0.0 0.145"/>
  </joint>
  <joint name="shoulder_joint" type="continuous">
    <axis xyz="0 1 0"/>
    <parent link="arm_base"/>
    <child link="bicep"/>
    <origin rpy="0 0 1.5708" xyz="-0.05166 0.0 0.20271"/>
  </joint>
  <joint name="bottom_wrist_joint" type="continuous">
    <axis xyz="0 1 0"/>
    <parent link="bicep"/>
    <child link="bottom_wrist"/>
    <origin rpy="0 0 0" xyz="0.0 -0.05194 0.269"/>
  </joint>
  <joint name="elbow_joint" type="continuous">
    <axis xyz="0 0 1"/>
    <parent link="bottom_wrist"/>
    <child link="elbow"/>
    <origin rpy="0 0 0" xyz="0.0 0 0.13522"/>
  </joint>
  <joint name="top_wrist_joint" type="continuous">
    <axis xyz="0 1 0"/>
    <parent link="elbow"/>
    <child link="top_wrist"/>
    <origin rpy="0 0 0" xyz="0.0 0 0.20994"/>
  </joint>
  <!-- Gripper -->
  <joint name="wrist_gripper_joint" type="continuous">
    <axis xyz="0 0 1"/>
    <parent link="top_wrist"/>
    <child link="test__link"/>
    <origin rpy="0 0 0" xyz="0.0 0 0.11"/>
  </joint>
  <joint name="test_link_0_joint_4" type="fixed">
    <parent link="test__link_0"/>
    <child link="test__link_0_clone_0"/>
    <origin rpy="-0.39713  1.57078 -0.39713" xyz="-0.085    0       0.01749"/>
  </joint>
  <joint name="test_link_joint_2" type="fixed">
    <parent link="test__link"/>
    <child link="test__link_0_clone"/>
    <origin rpy="-3.14159  1.57079 -3.14159" xyz="0.0625 0     0.175"/>
  </joint>
  <joint name="test_link_joint_3" type="prismatic">
    <parent link="test__link"/>
    <child link="test__link_0"/>
    <origin rpy="3.14159 1.57079 3.14159" xyz="-0.0625  0      0.15"/>
    <axis xyz="0 0 1"/>
    <limit effort="-1.0" lower="0" upper="0.075" velocity="-1.0"/>
  </joint>
  <link name="test__link">
    <inertial>
      <mass value="0.46875"/>
      <origin rpy="0 0 0" xyz="0 0 0"/>
      <inertia ixx="0.00019531" ixy="0" ixz="0" iyy="0.00097656" iyz="0" izz="0.00097656"/>
    </inertial>
    <collision name="test__collision">
      <origin rpy="0 0 0" xyz="0   0   0.05"/>
      <geometry>
        <box size="0.15 0.05 0.05"/>
      </geometry>
    </collision>
    <visual name="test__visual">
      <origin rpy="0 0 0" xyz="0   0   0.05"/>
      <geometry>
        <box size="0.15 0.05 0.05"/>
      </geometry>
    </visual>
  </link>
  <link name="test__link_0">
    <inertial>
      <mass value="0.234375"/>
      <origin rpy="0 0 0" xyz="0 0 0"/>
      <inertia ixx="6.104e-05" ixy="0" ixz="0" iyy="0.00045166" iyz="0" izz="0.00048828"/>
    </inertial>
    <collision name="test__collision">
      <origin rpy="0 0 0" xyz="0 0 0"/>
      <geometry>
        <box size="0.15 0.05 0.025"/>
      </geometry>
    </collision>
    <visual name="test__visual">
      <origin rpy="0 0 0" xyz="0 0 0"/>
      <geometry>
        <box size="0.15 0.05 0.025"/>
      </geometry>
    </visual>
  </link>
  <link name="test__link_0_clone">
    <inertial>
      <mass value="0.3125"/>
      <origin rpy="0 0 0" xyz="0 0 0"/>
      <inertia ixx="8.138e-05" ixy="0" ixz="0" iyy="0.00105794" iyz="0" izz="0.00110677"/>
    </inertial>
    <collision name="test__collision">
      <origin rpy="0 0 0" xyz="0 0 0"/>
      <geometry>
        <box size="0.2 0.05 0.025"/>
      </geometry>
    </collision>
    <visual name="test__visual">
      <origin rpy="0 0 0" xyz="0 0 0"/>
      <geometry>
        <box size="0.2 0.05 0.025"/>
      </geometry>
    </visual>
  </link>
  <link name="test__link_0_clone_0">
    <inertial>
      <mass value="0.075"/>
      <origin rpy="0 0 0" xyz="0 0 0"/>
      <inertia ixx="1.813e-05" ixy="0" ixz="0" iyy="2.5e-05" iyz="0" izz="3.812e-05"/>
    </inertial>
    <collision name="test__collision">
      <origin rpy="0 0 0" xyz="0 0 0"/>
      <geometry>
        <box size="0.06 0.05 0.02"/>
      </geometry>
    </collision>
    <visual name="test__visual">
      <origin rpy="0 0 0" xyz="0 0 0"/>
      <geometry>
        <box size="0.06 0.05 0.02"/>
      </geometry>
    </visual>
  </link>
  <!--########################## SENSORS ############################################-->
  <link name="laser_link">
    <collision>
      <origin rpy="0 0 0" xyz="0 0 0"/>
      <geometry>
        <box size="0.05 0.05 0.05"/>
      </geometry>
    </collision>
    <visual>
      <origin rpy="0 0 0" xyz="0 0 0"/>
      <geometry>
        <box size="0.05 0.05 0.05"/>
      </geometry>
    </visual>
    <inertial>
      <mass value="1e-5"/>
      <origin rpy="0 0 0" xyz="0 0 0"/>
      <inertia ixx="1e-6" ixy="0" ixz="0" iyy="1e-6" iyz="0" izz="1e-6"/>
    </inertial>
  </link>
  <joint name="laser_joint" type="fixed">
    <axis xyz="0 1 0"/>
    <origin rpy="0 0 0" xyz="0.350 0 0.055"/>
    <parent link="base_link"/>
    <child link="laser_link"/>
  </joint>
  <gazebo reference="laser_link">
    <sensor name="laser" type="ray">
      <pose>0 0 0 0 0 0</pose>
      <visualize>true</visualize>
      <update_rate>30</update_rate>
      <ray>
        <scan>
          <horizontal>
            <samples>720</samples>
            <resolution>1</resolution>
            <min_angle>-1.570796</min_angle>
            <max_angle>1.570796</max_angle>
          </horizontal>
        </scan>
        <range>
          <min>0.10</min>
          <max>30.0</max>
          <resolution>0.01</resolution>
        </range>
      </ray>
      <plugin filename="libgazebo_ros_laser.so" name="gazebo_ros_head_hokuyo_controller">
        <topicName>/scan</topicName>
        <frameName>laser_link</frameName>
      </plugin>
    </sensor>
  </gazebo>
  <link name="imu_link">
    <!-- Other link elements -->
    <inertial>
      <origin rpy="0 0 0" xyz="0 0 0"/>
      <mass value="1e-5"/>
      <inertia ixx="1e-6" ixy="0" ixz="0" iyy="1e-6" iyz="0" izz="1e-6"/>
    </inertial>
    <collision>
      <origin rpy="0 0 0" xyz="0 0 0"/>
      <geometry>
        <box size="0.025 0.025 0.025"/>
      </geometry>
    </collision>
    <visual>
      <origin rpy="0 0 0" xyz="0 0 0"/>
      <geometry>
        <box size="0.025 0.025 0.025"/>
      </geometry>
    </visual>
  </link>
  <joint name="imu_joint" type="fixed">
    <axis xyz="0 0 1"/>
    <!--0.0125-->
    <origin rpy="0 0 0" xyz="0.1 0.0 0.1625"/>
    <parent link="base_link"/>
    <child link="imu_link"/>
  </joint>
  <gazebo reference="imu_link">
    <gravity>true</gravity>
    <sensor name="imu_sensor" type="imu">
      <always_on>true</always_on>
      <update_rate>30</update_rate>
      <visualize>true</visualize>
      <topic>__default_topic__</topic>
      <plugin filename="libgazebo_ros_imu_sensor.so" name="imu_plugin">
        <topicName>imu_data</topicName>
        <serviceName>imu_service</serviceName>
        <bodyName>imu_link</bodyName>
        <updateRateHZ>10.0</updateRateHZ>
        <gaussianNoise>0.0</gaussianNoise>
        <xyzOffset>0 0 0</xyzOffset>
        <rpyOffset>0 0 0</rpyOffset>
        <frameName>imu_link</frameName>
        <initialOrientationAsReference>false</initialOrientationAsReference>
      </plugin>
      <pose>0 0 0 0 0 0</pose>
    </sensor>
  </gazebo>
  <link name="camera_link">
    <inertial>
      <mass value="0.1"/>
      <origin rpy="0 0 0" xyz="0 0 0"/>
      <inertia ixx="3.178895872" ixy="0" ixz="0" iyy="0.4" iyz="0" izz="3.157040640"/>
    </inertial>
    <collision name="collision">
      <geometry>
        <mesh filename="package://robot_description/meshes/kinect.dae"/>
        <!-- <box>
          <size>0.073000 0.276000 0.072000</size>
        </box> -->
      </geometry>
    </collision>
    <visual name="visual">
      <geometry>
        <mesh filename="package://robot_description/meshes/kinect.dae"/>
      </geometry>
    </visual>
  </link>
  <joint name="camera_joint" type="fixed">
    <axis xyz="0 0 1"/>
    <!-- -0.0025-->
    <origin rpy="0 0 0" xyz="0.22 0.0 0.2025"/>
    <parent link="base_link"/>
    <child link="camera_link"/>
  </joint>
  <gazebo reference="camera_link">
    <sensor name="camera" type="depth">
      <update_rate>20</update_rate>
      <camera>
        <horizontal_fov>1.047198</horizontal_fov>
        <image>
          <width>640</width>
          <height>480</height>
          <format>R8G8B8</format>
        </image>
        <clip>
          <near>0.05</near>
          <!-- <far>3</far> -->
        </clip>
      </camera>
      <plugin filename="libgazebo_ros_openni_kinect.so" name="camera_plugin">
        <baseline>0.2</baseline>
        <alwaysOn>true</alwaysOn>
        <!-- Keep this zero, update_rate in the parent <sensor> tag
          will control the frame rate. -->
        <updateRate>0.0</updateRate>
        <cameraName>camera_ir</cameraName>
        <imageTopicName>/camera/color/image_raw</imageTopicName>
        <cameraInfoTopicName>/camera/color/camera_info</cameraInfoTopicName>
        <depthImageTopicName>/camera/depth/image_raw</depthImageTopicName>
        <depthImageCameraInfoTopicName>/camera/depth/camera_info</depthImageCameraInfoTopicName>
        <pointCloudTopicName>/camera/depth/points</pointCloudTopicName>
        <frameName>camera_link</frameName>
        <pointCloudCutoff>0.5</pointCloudCutoff>
        <pointCloudCutoffMax>3.0</pointCloudCutoffMax>
        <distortionK1>0</distortionK1>
        <distortionK2>0</distortionK2>
        <distortionK3>0</distortionK3>
        <distortionT1>0</distortionT1>
        <distortionT2>0</distortionT2>
        <CxPrime>0</CxPrime>
        <Cx>0</Cx>
        <Cy>0</Cy>
        <focalLength>0</focalLength>
        <hackBaseline>0</hackBaseline>
      </plugin>
    </sensor>
  </gazebo>
  <!--########################### TRANSMISSIONS ############################################-->
  <!--########################## BASE TRANSMISSIONS ############################################-->
  <transmission name="front_left_wheel_trans" type="SimpleTransmission">
    <type>transmission_interface/SimpleTransmission</type>
    <actuator name="front_left_wheel_motor">
      <hardwareInterface>hardware_interface/VelocityJointInterface</hardwareInterface>
      <mechanicalReduction>1</mechanicalReduction>
    </actuator>
    <joint name="front_left_wheel_joint">
      <hardwareInterface>hardware_interface/VelocityJointInterface</hardwareInterface>
    </joint>
  </transmission>
  <transmission name="front_right_wheel_trans" type="SimpleTransmission">
    <type>transmission_interface/SimpleTransmission</type>
    <actuator name="front_right_wheel_motor">
      <hardwareInterface>hardware_interface/VelocityJointInterface</hardwareInterface>
      <mechanicalReduction>1</mechanicalReduction>
    </actuator>
    <joint name="front_right_wheel_joint">
      <hardwareInterface>hardware_interface/VelocityJointInterface</hardwareInterface>
    </joint>
  </transmission>
  <transmission name="rear_left_wheel_trans" type="SimpleTransmission">
    <type>transmission_interface/SimpleTransmission</type>
    <actuator name="rear_left_wheel_motor">
      <hardwareInterface>hardware_interface/VelocityJointInterface</hardwareInterface>
      <mechanicalReduction>1</mechanicalReduction>
    </actuator>
    <joint name="rear_left_wheel_joint">
      <hardwareInterface>hardware_interface/VelocityJointInterface</hardwareInterface>
    </joint>
  </transmission>
  <transmission name="rear_right_wheel_trans" type="SimpleTransmission">
    <type>transmission_interface/SimpleTransmission</type>
    <actuator name="rear_right_wheel_motor">
      <hardwareInterface>hardware_interface/VelocityJointInterface</hardwareInterface>
      <mechanicalReduction>1</mechanicalReduction>
    </actuator>
    <joint name="rear_right_wheel_joint">
      <hardwareInterface>hardware_interface/VelocityJointInterface</hardwareInterface>
    </joint>
  </transmission>
  <!--################################ ARM TRANSIMISSIONS ######################################-->
  <transmission name="arm_base_trans" type="SimpleTransmission">
    <type>transmission_interface/SimpleTransmission</type>
    <actuator name="arm_base_motor">
      <hardwareInterface>hardware_interface/PositionJointInterface</hardwareInterface>
      <mechanicalReduction>1</mechanicalReduction>
    </actuator>
    <joint name="arm_base_joint">
      <hardwareInterface>hardware_interface/PositionJointInterface</hardwareInterface>
    </joint>
  </transmission>
  <transmission name="shoulder_trans" type="SimpleTransmission">
    <type>transmission_interface/SimpleTransmission</type>
    <actuator name="shoulder_motor">
      <hardwareInterface>hardware_interface/PositionJointInterface</hardwareInterface>
      <mechanicalReduction>1</mechanicalReduction>
    </actuator>
    <joint name="shoulder_joint">
      <hardwareInterface>hardware_interface/PositionJointInterface</hardwareInterface>
    </joint>
  </transmission>
  <transmission name="bottom_wrist_trans" type="SimpleTransmission">
    <type>transmission_interface/SimpleTransmission</type>
    <actuator name="bottom_wrist_motor">
      <hardwareInterface>hardware_interface/PositionJointInterface</hardwareInterface>
      <mechanicalReduction>1</mechanicalReduction>
    </actuator>
    <joint name="bottom_wrist_joint">
      <hardwareInterface>hardware_interface/PositionJointInterface</hardwareInterface>
    </joint>
  </transmission>
  <transmission name="elbow_trans" type="SimpleTransmission">
    <type>transmission_interface/SimpleTransmission</type>
    <actuator name="elbow_motor">
      <hardwareInterface>hardware_interface/PositionJointInterface</hardwareInterface>
      <mechanicalReduction>1</mechanicalReduction>
    </actuator>
    <joint name="elbow_joint">
      <hardwareInterface>hardware_interface/PositionJointInterface</hardwareInterface>
    </joint>
  </transmission>
  <transmission name="top_wrist_trans" type="SimpleTransmission">
    <type>transmission_interface/SimpleTransmission</type>
    <actuator name="top_wrist_motor">
      <hardwareInterface>hardware_interface/PositionJointInterface</hardwareInterface>
      <mechanicalReduction>1</mechanicalReduction>
    </actuator>
    <joint name="top_wrist_joint">
      <hardwareInterface>hardware_interface/PositionJointInterface</hardwareInterface>
    </joint>
  </transmission>
  <transmission name="gripper_trans" type="SimpleTransmission">
    <type>transmission_interface/SimpleTransmission</type>
    <actuator name="link_JOINT_3_motor">
      <hardwareInterface>hardware_interface/PositionJointInterface</hardwareInterface>
      <mechanicalReduction>1</mechanicalReduction>
    </actuator>
    <joint name="test_link_joint_3">
      <hardwareInterface>hardware_interface/PositionJointInterface</hardwareInterface>
    </joint>
  </transmission>
  <transmission name="wrist_gripper_trans" type="SimpleTransmission">
    <type>transmission_interface/SimpleTransmission</type>
    <actuator name="wrist_gripper_motor">
      <hardwareInterface>hardware_interface/PositionJointInterface</hardwareInterface>
      <mechanicalReduction>1</mechanicalReduction>
    </actuator>
    <joint name="wrist_gripper_joint">
      <hardwareInterface>hardware_interface/PositionJointInterface</hardwareInterface>
    </joint>
  </transmission>
  <!--########################### GAZEBO ############################################-->
  <!--######################################################################-->
  <gazebo>
    <plugin filename="libgazebo_ros_control.so" name="gazebo_ros_control">
      <robotNamespace>/</robotNamespace>
      <controlPeriod>0.001</controlPeriod>
      <legacyModeNS>false</legacyModeNS>
    </plugin>
  </gazebo>
  <!--######################################################################-->
  <gazebo>
    <plugin filename="libgazebo_ros_joint_state_publisher.so" name="joint_state_publisher">
      <jointName>arm_base_joint, shoulder_joint, bottom_wrist_joint, elbow_joint, bottom_wrist_joint, top_wrist_joint, 
      wrist_gripper_joint, test_link_joint_3</jointName>
    </plugin>
  </gazebo>
  <!--######################################################################-->
  <!--######################################################################-->
  <gazebo>
    <plugin filename="libgazebo_ros_diff_drive.so" name="diff_drive_controller">
      <legacyMode>false</legacyMode>
      <alwaysOn>true</alwaysOn>
      <updateRate>1000.0</updateRate>
      <leftJoint>front_left_wheel_joint, rear_left_wheel_joint</leftJoint>
      <rightJoint>front_right_wheel_joint, rear_right_wheel_joint</rightJoint>
      <wheelSeparation>0.5</wheelSeparation>
      <wheelDiameter>0.2</wheelDiameter>
      <wheelTorque>10</wheelTorque>
      <publishTf>1</publishTf>
      <odometryFrame>map</odometryFrame>
      <commandTopic>cmd_vel</commandTopic>
      <odometryTopic>odom</odometryTopic>
      <robotBaseFrame>base_link</robotBaseFrame>
      <wheelAcceleration>2.8</wheelAcceleration>
      <publishWheelJointState>false</publishWheelJointState>
      <publishWheelTF>false</publishWheelTF>
      <publishOdomTF>false</publishOdomTF>
      <enable_odom_tf>false</enable_odom_tf>
      <odometrySource>world</odometrySource>
      <rosDebugLevel>Debug</rosDebugLevel>
    </plugin>
  </gazebo>
  <!--######################################################################-->
  <!--######################################################################-->
  <gazebo reference="front_left_wheel">
    <mu1 value="1.0"/>
    <mu2 value="1.0"/>
    <kp value="10000000.0"/>
    <kd value="1.0"/>
    <fdir1 value="1 0 0"/>
  </gazebo>
  <gazebo reference="front_right_wheel">
    <mu1 value="1.0"/>
    <mu2 value="1.0"/>
    <kp value="10000000.0"/>
    <kd value="1.0"/>
    <fdir1 value="1 0 0"/>
  </gazebo>
  <gazebo reference="rear_left_wheel">
    <mu1 value="1.0"/>
    <mu2 value="1.0"/>
    <kp value="10000000.0"/>
    <kd value="1.0"/>
    <fdir1 value="1 0 0"/>
  </gazebo>
  <gazebo reference="rear_right_wheel">
    <mu1 value="1.0"/>
    <mu2 value="1.0"/>
    <kp value="10000000.0"/>
    <kd value="1.0"/>
    <fdir1 value="1 0 0"/>
  </gazebo>
  <!--######################################################################-->
</robot>

